Workbook
Name moras: Hoja1!$A$1:$I$5001
Name moras_1: Imputacion!$A$1:$I$5001

Sheet Hoja1
A1: IDENTIFICACION | B1: SEXO | C1: SALARIO | D1: TIPO_ASEGURAMIENTO | E1: SECTOR | F1: INDICADOR_ACTIVO | G1: INDICADOR.EXTRANJERO | H1: INDICADOR_MOROSO | I1: EDAD | J1: Z-SCORE_SALARIO | K1: Z-SCORE_EDAD | L1: ES_ATIPICO_SALARIO | M1: ES_ATIPICO_EDAD
A2: 1 | B2: HOMBRE | D2: ASALARIADO | E2: SECTOR PUBLICO | F2: SI | G2: NO | H2: NO | I2: 42 | J2: =(C2-$Q$13)/$Q$14 -> -0.81076736 | K2: =(I2-$R$13)/$R$14 -> 0.0066098168 | L2: =IF(ABS(J2)> 1.96, "SI", "NO") -> NO | M2: =IF(ABS(K2)> 1.96, "SI", "NO") -> NO | P2: 2) Resumen
A3: 2 | B3: HOMBRE | C3: 3315014 | D3: PENSIONADOS EN SU PROPIO SISTEMA | E3: SECTOR PUBLICO | F3: SI | G3: NO | H3: NO | I3: 77 | J3: =(C3-$Q$13)/$Q$14 -> 3.276784 | K3: =(I3-$R$13)/$R$14 -> 2.4767464 | L3: =IF(ABS(J3)> 1.96, "SI", "NO") -> SI | M3: =IF(ABS(K3)> 1.96, "SI", "NO") -> SI
A4: 3 | B4: MUJER | C4: 270486.01 | D4: ASALARIADO | E4: SECTOR PRIVADO | F4: SI | G4: NO | H4: NO | I4: 45 | J4: =(C4-$Q$13)/$Q$14 -> -0.47724677 | K4: =(I4-$R$13)/$R$14 -> 0.21833581 | L4: =IF(ABS(J4)> 1.96, "SI", "NO") -> NO | M4: =IF(ABS(K4)> 1.96, "SI", "NO") -> NO | Q4: Salario | R4: Edad
A5: 4 | B5: MUJER | C5: 544949.83 | D5: ASALARIADO | E5: SECTOR PRIVADO | F5: SI | G5: NO | H5: NO | I5: 49 | J5: =(C5-$Q$13)/$Q$14 -> -0.13882136 | K5: =(I5-$R$13)/$R$14 -> 0.50063713 | L5: =IF(ABS(J5)> 1.96, "SI", "NO") -> NO | M5: =IF(ABS(K5)> 1.96, "SI", "NO") -> NO | P5: Minimo | Q5: =MIN(C2:C5001) -> 10 | R5: =MIN(I2:I5001) -> 14
A6: 5 | B6: MUJER | C6: 210000 | D6: ASALARIADO | E6: SECTOR PRIVADO | F6: SI | G6: NO | H6: NO | I6: 42 | J6: =(C6-$Q$13)/$Q$14 -> -0.55182855 | K6: =(I6-$R$13)/$R$14 -> 0.0066098168 | L6: =IF(ABS(J6)> 1.96, "SI", "NO") -> NO | M6: =IF(ABS(K6)> 1.96, "SI", "NO") -> NO | P6: Cuartil 1 | Q6: =_xlfn.QUARTILE.EXC(C2:C5001,1) -> 297354.5 | R6: =_xlfn.QUARTILE.EXC(I2:I5001,1) -> 31
A7: 6 | B7: HOMBRE | C7: 397150 | D7: ASALARIADO | E7: SECTOR PRIVADO | F7: SI | G7: NO | H7: NO | I7: 44 | J7: =(C7-$Q$13)/$Q$14 -> -0.32106475 | K7: =(I7-$R$13)/$R$14 -> 0.14776048 | L7: =IF(ABS(J7)> 1.96, "SI", "NO") -> NO | M7: =IF(ABS(K7)> 1.96, "SI", "NO") -> NO | P7: Mediana | Q7: =MEDIAN(C2:C5001) -> 408495 | R7: =MEDIAN(I2:I5001) -> 40
A8: 7 | B8: HOMBRE | C8: 854712 | D8: ASALARIADO | E8: SECTOR PRIVADO | F8: SI | G8: NO | H8: NO | I8: 38 | J8: =(C8-$Q$13)/$Q$14 -> 0.24312838 | K8: =(I8-$R$13)/$R$14 -> -0.2756915 | L8: =IF(ABS(J8)> 1.96, "SI", "NO") -> NO | M8: =IF(ABS(K8)> 1.96, "SI", "NO") -> NO | P8: Cuartil 3 | Q8: =_xlfn.QUARTILE.EXC(C2:C5001,3) -> 700000 | R8: =_xlfn.QUARTILE.EXC(I2:I5001,3) -> 52
A9: 8 | B9: HOMBRE | C9: 401000 | D9: ASALARIADO | E9: SECTOR PRIVADO | F9: SI | G9: SI | H9: SI | I9: 36 | J9: =(C9-$Q$13)/$Q$14 -> -0.31631754 | K9: =(I9-$R$13)/$R$14 -> -0.41684216 | L9: =IF(ABS(J9)> 1.96, "SI", "NO") -> NO | M9: =IF(ABS(K9)> 1.96, "SI", "NO") -> NO | P9: Máximo | Q9: =MAX(C2:C5001) -> 16858742 | R9: =MAX(I2:I5001) -> 99
A10: 9 | B10: MUJER | C10: 264703.96 | D10: ASALARIADO | E10: SECTOR PRIVADO | F10: SI | G10: NO | H10: NO | I10: 21 | J10: =(C10-$Q$13)/$Q$14 -> -0.48437628 | K10: =(I10-$R$13)/$R$14 -> -1.4754721 | L10: =IF(ABS(J10)> 1.96, "SI", "NO") -> NO | M10: =IF(ABS(K10)> 1.96, "SI", "NO") -> NO | P10: Promedio | Q10: =AVERAGE(C2:C5001) -> 657534.29 | R10: =AVERAGE(I2:I5001) -> 41.906344
A11: 10 | B11: HOMBRE | C11: 4677126.8 | D11: ASALARIADO | E11: SECTOR PRIVADO | F11: SI | G11: NO | H11: NO | I11: 40 | J11: =(C11-$Q$13)/$Q$14 -> 4.9563262 | K11: =(I11-$R$13)/$R$14 -> -0.13454084 | L11: =IF(ABS(J11)> 1.96, "SI", "NO") -> SI | M11: =IF(ABS(K11)> 1.96, "SI", "NO") -> NO | P11: 3)
A12: 11 | B12: MUJER | C12: 1200000 | D12: ASALARIADO | E12: SECTOR PRIVADO | F12: SI | G12: NO | H12: NO | I12: 30 | J12: =(C12-$Q$13)/$Q$14 -> 0.66888297 | K12: =(I12-$R$13)/$R$14 -> -0.84029414 | L12: =IF(ABS(J12)> 1.96, "SI", "NO") -> NO | M12: =IF(ABS(K12)> 1.96, "SI", "NO") -> NO | Q12: Salario | R12: Edad
A13: 12 | B13: MUJER | C13: 1030132 | D13: ASALARIADO | E13: SECTOR PUBLICO | F13: SI | G13: NO | H13: SI | I13: 58 | J13: =(C13-$Q$13)/$Q$14 -> 0.4594286 | K13: =(I13-$R$13)/$R$14 -> 1.1358151 | L13: =IF(ABS(J13)> 1.96, "SI", "NO") -> NO | M13: =IF(ABS(K13)> 1.96, "SI", "NO") -> NO | P13: Promedio | Q13: =AVERAGE(C2:C5001) -> 657534.29 | R13: =AVERAGE(I2:I5001) -> 41.906344
A14: 13 | B14: HOMBRE | C14: 731287.5 | D14: ASALARIADO | E14: SECTOR PUBLICO | F14: SI | G14: NO | H14: NO | I14: 40 | J14: =(C14-$Q$13)/$Q$14 -> 0.090940799 | K14: =(I14-$R$13)/$R$14 -> -0.13454084 | L14: =IF(ABS(J14)> 1.96, "SI", "NO") -> NO | M14: =IF(ABS(K14)> 1.96, "SI", "NO") -> NO | P14: Des.estand. | Q14: =_xlfn.STDEV.S(C2:C5001) -> 811002.42 | R14: =_xlfn.STDEV.S(I2:I5001) -> 14.169257
A15: 14 | B15: HOMBRE | C15: 282305 | D15: ASEGURADO VOLUNTARIO | E15: SECTOR PRIVADO | F15: SI | G15: NO | H15: NO | I15: 51 | J15: =(C15-$Q$13)/$Q$14 -> -0.46267346 | K15: =(I15-$R$13)/$R$14 -> 0.64178779 | L15: =IF(ABS(J15)> 1.96, "SI", "NO") -> NO | M15: =IF(ABS(K15)> 1.96, "SI", "NO") -> NO
A16: 15 | B16: MUJER | C16: 343390.86 | D16: TRABAJADOR INDEPENDIENTE | E16: SECTOR PRIVADO | F16: SI | G16: NO | H16: NO | I16: 59 | J16: =(C16-$Q$13)/$Q$14 -> -0.38735203 | K16: =(I16-$R$13)/$R$14 -> 1.2063904 | L16: =IF(ABS(J16)> 1.96, "SI", "NO") -> NO | M16: =IF(ABS(K16)> 1.96, "SI", "NO") -> NO | P16: 4)
A17: 16 | B17: MUJER | C17: 1943489.5 | D17: ASALARIADO | E17: SECTOR PUBLICO | F17: SI | G17: NO | H17: NO | I17: 58 | J17: =(C17-$Q$13)/$Q$14 -> 1.5856367 | K17: =(I17-$R$13)/$R$14 -> 1.1358151 | L17: =IF(ABS(J17)> 1.96, "SI", "NO") -> NO | M17: =IF(ABS(K17)> 1.96, "SI", "NO") -> NO | Q17: IDENTIFICACION | R17: SEXO | S17: SALARIO | T17: TIPO_ASEGURAMIENTO | U17: SECTOR | V17: INDICADOR_ACTIVO | W17: INDICADOR.EXTRANJERO | X17: INDICADOR_MOROSO | Y17: EDAD
A18: 17 | B18: MUJER | C18: 1108980 | D18: ASALARIADO | E18: SECTOR PUBLICO | F18: SI | G18: NO | H18: SI | I18: 36 | J18: =(C18-$Q$13)/$Q$14 -> 0.55665149 | K18: =(I18-$R$13)/$R$14 -> -0.41684216 | L18: =IF(ABS(J18)> 1.96, "SI", "NO") -> NO | M18: =IF(ABS(K18)> 1.96, "SI", "NO") -> NO | P18: Valores faltantes | Q18: =COUNTBLANK(A2:A5001) -> 0 | R18: =COUNTBLANK(B2:B5001) -> 0 | S18: =COUNTBLANK(C2:C5001) -> 3 | T18: =COUNTBLANK(D2:D5001) -> 2 | U18: =COUNTBLANK(E2:E5001) -> 0 | V18: =COUNTBLANK(F2:F5001) -> 0 | W18: =COUNTBLANK(G2:G5001) -> 0 | X18: =COUNTBLANK(H2:H5001) -> 0 | Y18: =COUNTBLANK(I2:I5001) -> 3
A19: 18 | B19: MUJER | C19: 133157 | D19: ASALARIADO | E19: SECTOR PRIVADO | F19: SI | G19: NO | H19: NO | I19: 39 | J19: =(C19-$Q$13)/$Q$14 -> -0.6465792 | K19: =(I19-$R$13)/$R$14 -> -0.20511617 | L19: =IF(ABS(J19)> 1.96, "SI", "NO") -> NO | M19: =IF(ABS(K19)> 1.96, "SI", "NO") -> NO | P19: Porcentaje NA | Q19: =Q18/5000*100 -> 0 | R19: =R18/5000*100 -> 0 | S19: =S18/5000*100 -> 0.06 | T19: =T18/5000*100 -> 0.04 | U19: =U18/5000*100 -> 0 | V19: =V18/5000*100 -> 0 | W19: =W18/5000*100 -> 0 | X19: =X18/5000*100 -> 0 | Y19: =Y18/5000*100 -> 0.06
A20: 19 | B20: HOMBRE | C20: 553939 | D20: ASALARIADO | E20: SECTOR PRIVADO | F20: SI | G20: NO | H20: NO | I20: 45 | J20: =(C20-$Q$13)/$Q$14 -> -0.12773734 | K20: =(I20-$R$13)/$R$14 -> 0.21833581 | L20: =IF(ABS(J20)> 1.96, "SI", "NO") -> NO | M20: =IF(ABS(K20)> 1.96, "SI", "NO") -> NO
A21: 20 | B21: MUJER | C21: 309820 | D21: ASEGURADO VOLUNTARIO | E21: SECTOR PRIVADO | F21: SI | G21: SI | H21: SI | I21: 52 | J21: =(C21-$Q$13)/$Q$14 -> -0.42874631 | K21: =(I21-$R$13)/$R$14 -> 0.71236312 | L21: =IF(ABS(J21)> 1.96, "SI", "NO") -> NO | M21: =IF(ABS(K21)> 1.96, "SI", "NO") -> NO | P21: 5)
A22: 21 | B22: MUJER | D22: ASALARIADO | E22: SECTOR PRIVADO | F22: SI | G22: SI | H22: NO | I22: 28 | J22: =(C22-$Q$13)/$Q$14 -> -0.81076736 | K22: =(I22-$R$13)/$R$14 -> -0.9814448 | L22: =IF(ABS(J22)> 1.96, "SI", "NO") -> NO | M22: =IF(ABS(K22)> 1.96, "SI", "NO") -> NO | P22: Para esto voy a imputar mediante el promedio. Creo una nueva hoja llamada Imputacion y ahí imputo la tabla
A23: 22 | B23: HOMBRE | C23: 278030 | D23: CONVENIOS ESPECIALES DE TRABAJADORES INDEPENDIENTES | E23: SECTOR PRIVADO | F23: SI | G23: NO | H23: NO | I23: 59 | J23: =(C23-$Q$13)/$Q$14 -> -0.46794471 | K23: =(I23-$R$13)/$R$14 -> 1.2063904 | L23: =IF(ABS(J23)> 1.96, "SI", "NO") -> NO | M23: =IF(ABS(K23)> 1.96, "SI", "NO") -> NO | P23: Para el caso de TIPO_ASEGURAMIENTO busco la moda
A24: 23 | B24: HOMBRE | C24: 2124814 | D24: ASALARIADO | E24: SECTOR PRIVADO | F24: SI | G24: NO | H24: NO | I24: 32 | J24: =(C24-$Q$13)/$Q$14 -> 1.8092174 | K24: =(I24-$R$13)/$R$14 -> -0.69914348 | L24: =IF(ABS(J24)> 1.96, "SI", "NO") -> NO | M24: =IF(ABS(K24)> 1.96, "SI", "NO") -> NO
A25: 24 | B25: HOMBRE | C25: 191744.68 | D25: ASALARIADO | E25: SECTOR PRIVADO | F25: SI | G25: NO | H25: NO | I25: 18 | J25: =(C25-$Q$13)/$Q$14 -> -0.57433813 | K25: =(I25-$R$13)/$R$14 -> -1.6871981 | L25: =IF(ABS(J25)> 1.96, "SI", "NO") -> NO | M25: =IF(ABS(K25)> 1.96, "SI", "NO") -> NO | P25: Asalariado | Q25: =COUNTIF(D2:D5001,"Asalariado") -> 3462 | R25: como solo son cinco mil datos esta es la moda
A26: 25 | B26: MUJER | C26: 1117489 | D26: ASALARIADO | E26: SECTOR PUBLICO | F26: SI | G26: NO | H26: SI | I26: 36 | J26: =(C26-$Q$13)/$Q$14 -> 0.56714345 | K26: =(I26-$R$13)/$R$14 -> -0.41684216 | L26: =IF(ABS(J26)> 1.96, "SI", "NO") -> NO | M26: =IF(ABS(K26)> 1.96, "SI", "NO") -> NO
A27: 26 | B27: HOMBRE | C27: 1451530 | D27: PENSIONADOS EN SU PROPIO SISTEMA | E27: SECTOR PUBLICO | F27: SI | G27: NO | H27: NO | I27: 62 | J27: =(C27-$Q$13)/$Q$14 -> 0.97903001 | K27: =(I27-$R$13)/$R$14 -> 1.4181164 | L27: =IF(ABS(J27)> 1.96, "SI", "NO") -> NO | M27: =IF(ABS(K27)> 1.96, "SI", "NO") -> NO | P27: 6)
A28: 27 | B28: HOMBRE | C28: 66700 | D28: ASALARIADO | E28: SECTOR PRIVADO | F28: SI | G28: NO | H28: NO | I28: 38 | J28: =(C28-$Q$13)/$Q$14 -> -0.72852347 | K28: =(I28-$R$13)/$R$14 -> -0.2756915 | L28: =IF(ABS(J28)> 1.96, "SI", "NO") -> NO | M28: =IF(ABS(K28)> 1.96, "SI", "NO") -> NO
A29: 28 | B29: MUJER | C29: 73410 | D29: ASALARIADO | E29: SECTOR PRIVADO | F29: SI | G29: SI | H29: NO | I29: 22 | J29: =(C29-$Q$13)/$Q$14 -> -0.72024975 | K29: =(I29-$R$13)/$R$14 -> -1.4048968 | L29: =IF(ABS(J29)> 1.96, "SI", "NO") -> NO | M29: =IF(ABS(K29)> 1.96, "SI", "NO") -> NO
A30: 29 | B30: HOMBRE | C30: 815355.66 | D30: ASALARIADO | E30: SECTOR PUBLICO | F30: SI | G30: NO | H30: NO | I30: 42 | J30: =(C30-$Q$13)/$Q$14 -> 0.19460037 | K30: =(I30-$R$13)/$R$14 -> 0.0066098168 | L30: =IF(ABS(J30)> 1.96, "SI", "NO") -> NO | M30: =IF(ABS(K30)> 1.96, "SI", "NO") -> NO
A31: 30 | B31: HOMBRE | C31: 398125 | D31: ASALARIADO | E31: SECTOR PRIVADO | F31: SI | G31: NO | H31: NO | I31: 38 | J31: =(C31-$Q$13)/$Q$14 -> -0.31986254 | K31: =(I31-$R$13)/$R$14 -> -0.2756915 | L31: =IF(ABS(J31)> 1.96, "SI", "NO") -> NO | M31: =IF(ABS(K31)> 1.96, "SI", "NO") -> NO
A32: 31 | B32: HOMBRE | C32: 606763.96 | D32: ASALARIADO | E32: SECTOR PRIVADO | F32: SI | G32: NO | H32: NO | I32: 39 | J32: =(C32-$Q$13)/$Q$14 -> -0.062601949 | K32: =(I32-$R$13)/$R$14 -> -0.20511617 | L32: =IF(ABS(J32)> 1.96, "SI", "NO") -> NO | M32: =IF(ABS(K32)> 1.96, "SI", "NO") -> NO
A33: 32 | B33: HOMBRE | C33: 360420 | D33: TRABAJADOR INDEPENDIENTE | E33: SECTOR PRIVADO | F33: SI | G33: NO | H33: SI | I33: 53 | J33: =(C33-$Q$13)/$Q$14 -> -0.36635439 | K33: =(I33-$R$13)/$R$14 -> 0.78293845 | L33: =IF(ABS(J33)> 1.96, "SI", "NO") -> NO | M33: =IF(ABS(K33)> 1.96, "SI", "NO") -> NO
A34: 33 | B34: MUJER | C34: 297046 | D34: ASALARIADO | E34: SECTOR PRIVADO | F34: SI | G34: SI | H34: NO | I34: 41 | J34: =(C34-$Q$13)/$Q$14 -> -0.44449719 | K34: =(I34-$R$13)/$R$14 -> -0.063965513 | L34: =IF(ABS(J34)> 1.96, "SI", "NO") -> NO | M34: =IF(ABS(K34)> 1.96, "SI", "NO") -> NO
A35: 34 | B35: HOMBRE | C35: 558030 | D35: ASALARIADO | E35: SECTOR PRIVADO | F35: SI | G35: NO | H35: NO | I35: 28 | J35: =(C35-$Q$13)/$Q$14 -> -0.12269297 | K35: =(I35-$R$13)/$R$14 -> -0.9814448 | L35: =IF(ABS(J35)> 1.96, "SI", "NO") -> NO | M35: =IF(ABS(K35)> 1.96, "SI", "NO") -> NO
A36: 35 | B36: HOMBRE | C36: 68309.03 | D36: ASALARIADO | E36: SECTOR PRIVADO | F36: SI | G36: NO | H36: NO | I36: 43 | J36: =(C36-$Q$13)/$Q$14 -> -0.72653946 | K36: =(I36-$R$13)/$R$14 -> 0.077185147 | L36: =IF(ABS(J36)> 1.96, "SI", "NO") -> NO | M36: =IF(ABS(K36)> 1.96, "SI", "NO") -> NO
A37: 36 | B37: HOMBRE | D37: ASALARIADO | E37: SECTOR PUBLICO | F37: SI | G37: NO | H37: NO | I37: 62 | J37: =(C37-$Q$13)/$Q$14 -> -0.81076736 | K37: =(I37-$R$13)/$R$14 -> 1.4181164 | L37: =IF(ABS(J37)> 1.96, "SI", "NO") -> NO | M37: =IF(ABS(K37)> 1.96, "SI", "NO") -> NO
A38: 37 | B38: HOMBRE | C38: 1552307.5 | D38: ASALARIADO | E38: SECTOR PRIVADO | F38: SI | G38: SI | H38: NO | I38: 41 | J38: =(C38-$Q$13)/$Q$14 -> 1.1032929 | K38: =(I38-$R$13)/$R$14 -> -0.063965513 | L38: =IF(ABS(J38)> 1.96, "SI", "NO") -> NO | M38: =IF(ABS(K38)> 1.96, "SI", "NO") -> NO
A39: 38 | B39: HOMBRE | C39: 1531575 | D39: ASEGURADO VOLUNTARIO | E39: SECTOR PRIVADO | F39: SI | G39: SI | H39: NO | I39: 66 | J39: =(C39-$Q$13)/$Q$14 -> 1.0777289 | K39: =(I39-$R$13)/$R$14 -> 1.7004177 | L39: =IF(ABS(J39)> 1.96, "SI", "NO") -> NO | M39: =IF(ABS(K39)> 1.96, "SI", "NO") -> NO
A40: 39 | B40: HOMBRE | C40: 3220569.1 | D40: ASALARIADO | E40: SECTOR PRIVADO | F40: SI | G40: NO | H40: NO | I40: 48 | J40: =(C40-$Q$13)/$Q$14 -> 3.1603294 | K40: =(I40-$R$13)/$R$14 -> 0.4300618 | L40: =IF(ABS(J40)> 1.96, "SI", "NO") -> SI | M40: =IF(ABS(K40)> 1.96, "SI", "NO") -> NO
...

Sheet Imputacion
A1: IDENTIFICACION | B1: SEXO | C1: SALARIO | D1: TIPO_ASEGURAMIENTO | E1: SECTOR | F1: INDICADOR_ACTIVO | G1: INDICADOR.EXTRANJERO | H1: INDICADOR_MOROSO | I1: EDAD | J1: MOROSO_BIN | K1: RANGO_SALARIO | L1: RANGO_EDAD
A2: 1 | B2: HOMBRE | C2: =IF(ISBLANK(Hoja1!C2),AVERAGE(Hoja1!$C$2:$C$5001),Hoja1!C2) -> 657534.29 | D2: =IF(ISBLANK(Hoja1!D2),"ASALARIADO",Hoja1!D2) -> ASALARIADO | E2: SECTOR PUBLICO | F2: SI | G2: NO | H2: NO | I2: =IF(ISBLANK(Hoja1!I2),AVERAGE(Hoja1!$I$2:$I$5001),Hoja1!I2) -> 42 | J2: =IF(H2="SI",1,0) -> 0 | K2: =IF(C2<=400000,"0-400k",IF(C2<=800000,"400k-800k",IF(C2<=1200000,"800k-1.2M",IF(C2<=2000000,"1.2M-2M","2M+")))) -> 400k-800k | L2: =IF(I2<=30,"18-30",IF(I2<=45,"31-45",IF(I2<=60,"46-60",IF(I2<=75,"61-75","76-100+")))) -> 31-45
A3: 2 | B3: HOMBRE | C3: =IF(ISBLANK(Hoja1!C3),AVERAGE(Hoja1!$C$2:$C$5001),Hoja1!C3) -> 3315014 | D3: =IF(ISBLANK(Hoja1!D3),"ASALARIADO",Hoja1!D3) -> PENSIONADOS EN SU PROPIO SISTEMA | E3: SECTOR PUBLICO | F3: SI | G3: NO | H3: NO | I3: =IF(ISBLANK(Hoja1!I3),AVERAGE(Hoja1!$I$2:$I$5001),Hoja1!I3) -> 77 | J3: =IF(H3="SI",1,0) -> 0 | K3: =IF(C3<=400000,"0-400k",IF(C3<=800000,"400k-800k",IF(C3<=1200000,"800k-1.2M",IF(C3<=2000000,"1.2M-2M","2M+")))) -> 2M+ | L3: =IF(I3<=30,"18-30",IF(I3<=45,"31-45",IF(I3<=60,"46-60",IF(I3<=75,"61-75","76-100+")))) -> 76-100+
A4: 3 | B4: MUJER | C4: =IF(ISBLANK(Hoja1!C4),AVERAGE(Hoja1!$C$2:$C$5001),Hoja1!C4) -> 270486.01 | D4: =IF(ISBLANK(Hoja1!D4),"ASALARIADO",Hoja1!D4) -> ASALARIADO | E4: SECTOR PRIVADO | F4: SI | G4: NO | H4: NO | I4: =IF(ISBLANK(Hoja1!I4),AVERAGE(Hoja1!$I$2:$I$5001),Hoja1!I4) -> 45 | J4: =IF(H4="SI",1,0) -> 0 | K4: =IF(C4<=400000,"0-400k",IF(C4<=800000,"400k-800k",IF(C4<=1200000,"800k-1.2M",IF(C4<=2000000,"1.2M-2M","2M+")))) -> 0-400k | L4: =IF(I4<=30,"18-30",IF(I4<=45,"31-45",IF(I4<=60,"46-60",IF(I4<=75,"61-75","76-100+")))) -> 31-45
A5: 4 | B5: MUJER | C5: =IF(ISBLANK(Hoja1!C5),AVERAGE(Hoja1!$C$2:$C$5001),Hoja1!C5) -> 544949.83 | D5: =IF(ISBLANK(Hoja1!D5),"ASALARIADO",Hoja1!D5) -> ASALARIADO | E5: SECTOR PRIVADO | F5: SI | G5: NO | H5: NO | I5: =IF(ISBLANK(Hoja1!I5),AVERAGE(Hoja1!$I$2:$I$5001),Hoja1!I5) -> 49 | J5: =IF(H5="SI",1,0) -> 0 | K5: =IF(C5<=400000,"0-400k",IF(C5<=800000,"400k-800k",IF(C5<=1200000,"800k-1.2M",IF(C5<=2000000,"1.2M-2M","2M+")))) -> 400k-800k | L5: =IF(I5<=30,"18-30",IF(I5<=45,"31-45",IF(I5<=60,"46-60",IF(I5<=75,"61-75","76-100+")))) -> 46-60
A6: 5 | B6: MUJER | C6: =IF(ISBLANK(Hoja1!C6),AVERAGE(Hoja1!$C$2:$C$5001),Hoja1!C6) -> 210000 | D6: =IF(ISBLANK(Hoja1!D6),"ASALARIADO",Hoja1!D6) -> ASALARIADO | E6: SECTOR PRIVADO | F6: SI | G6: NO | H6: NO | I6: =IF(ISBLANK(Hoja1!I6),AVERAGE(Hoja1!$I$2:$I$5001),Hoja1!I6) -> 42 | J6: =IF(H6="SI",1,0) -> 0 | K6: =IF(C6<=400000,"0-400k",IF(C6<=800000,"400k-800k",IF(C6<=1200000,"800k-1.2M",IF(C6<=2000000,"1.2M-2M","2M+")))) -> 0-400k | L6: =IF(I6<=30,"18-30",IF(I6<=45,"31-45",IF(I6<=60,"46-60",IF(I6<=75,"61-75","76-100+")))) -> 31-45
A7: 6 | B7: HOMBRE | C7: =IF(ISBLANK(Hoja1!C7),AVERAGE(Hoja1!$C$2:$C$5001),Hoja1!C7) -> 397150 | D7: =IF(ISBLANK(Hoja1!D7),"ASALARIADO",Hoja1!D7) -> ASALARIADO | E7: SECTOR PRIVADO | F7: SI | G7: NO | H7: NO | I7: =IF(ISBLANK(Hoja1!I7),AVERAGE(Hoja1!$I$2:$I$5001),Hoja1!I7) -> 44 | J7: =IF(H7="SI",1,0) -> 0 | K7: =IF(C7<=400000,"0-400k",IF(C7<=800000,"400k-800k",IF(C7<=1200000,"800k-1.2M",IF(C7<=2000000,"1.2M-2M","2M+")))) -> 0-400k | L7: =IF(I7<=30,"18-30",IF(I7<=45,"31-45",IF(I7<=60,"46-60",IF(I7<=75,"61-75","76-100+")))) -> 31-45
A8: 7 | B8: HOMBRE | C8: =IF(ISBLANK(Hoja1!C8),AVERAGE(Hoja1!$C$2:$C$5001),Hoja1!C8) -> 854712 | D8: =IF(ISBLANK(Hoja1!D8),"ASALARIADO",Hoja1!D8) -> ASALARIADO | E8: SECTOR PRIVADO | F8: SI | G8: NO | H8: NO | I8: =IF(ISBLANK(Hoja1!I8),AVERAGE(Hoja1!$I$2:$I$5001),Hoja1!I8) -> 38 | J8: =IF(H8="SI",1,0) -> 0 | K8: =IF(C8<=400000,"0-400k",IF(C8<=800000,"400k-800k",IF(C8<=1200000,"800k-1.2M",IF(C8<=2000000,"1.2M-2M","2M+")))) -> 800k-1.2M | L8: =IF(I8<=30,"18-30",IF(I8<=45,"31-45",IF(I8<=60,"46-60",IF(I8<=75,"61-75","76-100+")))) -> 31-45
A9: 8 | B9: HOMBRE | C9: =IF(ISBLANK(Hoja1!C9),AVERAGE(Hoja1!$C$2:$C$5001),Hoja1!C9) -> 401000 | D9: =IF(ISBLANK(Hoja1!D9),"ASALARIADO",Hoja1!D9) -> ASALARIADO | E9: SECTOR PRIVADO | F9: SI | G9: SI | H9: SI | I9: =IF(ISBLANK(Hoja1!I9),AVERAGE(Hoja1!$I$2:$I$5001),Hoja1!I9) -> 36 | J9: =IF(H9="SI",1,0) -> 1 | K9: =IF(C9<=400000,"0-400k",IF(C9<=800000,"400k-800k",IF(C9<=1200000,"800k-1.2M",IF(C9<=2000000,"1.2M-2M","2M+")))) -> 400k-800k | L9: =IF(I9<=30,"18-30",IF(I9<=45,"31-45",IF(I9<=60,"46-60",IF(I9<=75,"61-75","76-100+")))) -> 31-45
A10: 9 | B10: MUJER | C10: =IF(ISBLANK(Hoja1!C10),AVERAGE(Hoja1!$C$2:$C$5001),Hoja1!C10) -> 264703.96 | D10: =IF(ISBLANK(Hoja1!D10),"ASALARIADO",Hoja1!D10) -> ASALARIADO | E10: SECTOR PRIVADO | F10: SI | G10: NO | H10: NO | I10: =IF(ISBLANK(Hoja1!I10),AVERAGE(Hoja1!$I$2:$I$5001),Hoja1!I10) -> 21 | J10: =IF(H10="SI",1,0) -> 0 | K10: =IF(C10<=400000,"0-400k",IF(C10<=800000,"400k-800k",IF(C10<=1200000,"800k-1.2M",IF(C10<=2000000,"1.2M-2M","2M+")))) -> 0-400k | L10: =IF(I10<=30,"18-30",IF(I10<=45,"31-45",IF(I10<=60,"46-60",IF(I10<=75,"61-75","76-100+")))) -> 18-30
A11: 10 | B11: HOMBRE | C11: =IF(ISBLANK(Hoja1!C11),AVERAGE(Hoja1!$C$2:$C$5001),Hoja1!C11) -> 4677126.8 | D11: =IF(ISBLANK(Hoja1!D11),"ASALARIADO",Hoja1!D11) -> ASALARIADO | E11: SECTOR PRIVADO | F11: SI | G11: NO | H11: NO | I11: =IF(ISBLANK(Hoja1!I11),AVERAGE(Hoja1!$I$2:$I$5001),Hoja1!I11) -> 40 | J11: =IF(H11="SI",1,0) -> 0 | K11: =IF(C11<=400000,"0-400k",IF(C11<=800000,"400k-800k",IF(C11<=1200000,"800k-1.2M",IF(C11<=2000000,"1.2M-2M","2M+")))) -> 2M+ | L11: =IF(I11<=30,"18-30",IF(I11<=45,"31-45",IF(I11<=60,"46-60",IF(I11<=75,"61-75","76-100+")))) -> 31-45
A12: 11 | B12: MUJER | C12: =IF(ISBLANK(Hoja1!C12),AVERAGE(Hoja1!$C$2:$C$5001),Hoja1!C12) -> 1200000 | D12: =IF(ISBLANK(Hoja1!D12),"ASALARIADO",Hoja1!D12) -> ASALARIADO | E12: SECTOR PRIVADO | F12: SI | G12: NO | H12: NO | I12: =IF(ISBLANK(Hoja1!I12),AVERAGE(Hoja1!$I$2:$I$5001),Hoja1!I12) -> 30 | J12: =IF(H12="SI",1,0) -> 0 | K12: =IF(C12<=400000,"0-400k",IF(C12<=800000,"400k-800k",IF(C12<=1200000,"800k-1.2M",IF(C12<=2000000,"1.2M-2M","2M+")))) -> 800k-1.2M | L12: =IF(I12<=30,"18-30",IF(I12<=45,"31-45",IF(I12<=60,"46-60",IF(I12<=75,"61-75","76-100+")))) -> 18-30
A13: 12 | B13: MUJER | C13: =IF(ISBLANK(Hoja1!C13),AVERAGE(Hoja1!$C$2:$C$5001),Hoja1!C13) -> 1030132 | D13: =IF(ISBLANK(Hoja1!D13),"ASALARIADO",Hoja1!D13) -> ASALARIADO | E13: SECTOR PUBLICO | F13: SI | G13: NO | H13: SI | I13: =IF(ISBLANK(Hoja1!I13),AVERAGE(Hoja1!$I$2:$I$5001),Hoja1!I13) -> 58 | J13: =IF(H13="SI",1,0) -> 1 | K13: =IF(C13<=400000,"0-400k",IF(C13<=800000,"400k-800k",IF(C13<=1200000,"800k-1.2M",IF(C13<=2000000,"1.2M-2M","2M+")))) -> 800k-1.2M | L13: =IF(I13<=30,"18-30",IF(I13<=45,"31-45",IF(I13<=60,"46-60",IF(I13<=75,"61-75","76-100+")))) -> 46-60
... A5001: 5000 | B5001: HOMBRE | C5001: =IF(ISBLANK(Hoja1!C5001),AVERAGE(Hoja1!$C$2:$C$5001),Hoja1!C5001) -> 489078.33 | D5001: =IF(ISBLANK(Hoja1!D5001),"ASALARIADO",Hoja1!D5001) -> ASALARIADO | E5001: SECTOR PRIVADO | F5001: SI | G5001: NO | H5001: NO | I5001: =IF(ISBLANK(Hoja1!I5001),AVERAGE(Hoja1!$I$2:$I$5001),Hoja1!I5001) -> 41 | J5001: =IF(H5001="SI",1,0) -> 0 | K5001: =IF(C5001<=400000,"0-400k",IF(C5001<=800000,"400k-800k",IF(C5001<=1200000,"800k-1.2M",IF(C5001<=2000000,"1.2M-2M","2M+")))) -> 400k-800k | L5001: =IF(I5001<=30,"18-30",IF(I5001<=45,"31-45",IF(I5001<=60,"46-60",IF(I5001<=75,"61-75","76-100+")))) -> 31-45
